Workbook

Sheet Объем
A1: Дата | B1: Премии (за квартал) | C1: Выплаты (за квартал) | D1: Темп прироста премий, г/г (правая шкала) | E1: Темп прироста выплат г/г (правая шкала)
A2: I кв. 2020 | B2: 426272.4 | C2: 159473.6 | D2: 12.593123 | E2: 14.551099
A3: II кв. 2020 | B3: 312775.21 | C3: 137211.86 | D3: -13.275329 | E3: -6.2618583
A4: III кв. 2020 | B4: 396828.98 | C4: 167988.02 | D4: 9.5945734 | E4: 13.546372
A5: IV кв. 2020 | B5: 405055.32 | C5: 194574.78 | D5: 6.9165729 | E5: 10.511271
A6: I кв. 2021 | B6: 459799.28 | C6: 185252.35 | D6: =(B6-B2)/B2 * 100 -> 7.8651304 | E6: =(C6-C2)/C2*100 -> 16.164904
A7: II кв. 2021 | B7: 434384.19 | C7: 199237.79 | D7: =(B7-B3)/B3 * 100 -> 38.880634 | E7: =(C7-C3)/C3*100 -> 45.204496
A8: III кв. 2021 | B8: 461943.85 | C8: 203008.65 | D8: =(B8-B4)/B4 * 100 -> 16.408801 | E8: =(C8-C4)/C4*100 -> 20.847104
A9: IV кв. 2021 | B9: 448133.96 | C9: 209475.05 | D9: =(B9-B5)/B5 * 100 -> 10.635249 | E9: =(C9-C5)/C5*100 -> 7.6578612
A10: I кв. 2022 | B10: 452281.34 | C10: 201348.37 | D10: =(B10-B6)/B6 * 100 -> -1.6350478 | E10: =(C10-C6)/C6*100 -> 8.6886976
A11: II кв. 2022 | B11: 409975.84 | C11: 221333.1 | D11: =(B11-B7)/B7 * 100 -> -5.6190696 | E11: =(C11-C7)/C7*100 -> 11.089915
A12: III кв. 2022 | B12: 465677.53 | C12: 224211.44 | D12: =(B12-B8)/B8 * 100 -> 0.80825341 | E12: =(C12-C8)/C8*100 -> 10.444275
A13: IV кв. 2022 | B13: 488812.93 | C13: 246325.88 | D13: =(B13-B9)/B9 * 100 -> 9.0774126 | E13: =(C13-C9)/C9*100 -> 17.591988
A14: I кв. 2023 | B14: 548353.86 | C14: 245352.89 | D14: =(B14-B10)/B10 * 100 -> 21.241761 | E14: =(C14-C10)/C10*100 -> 21.854917
A15: II кв. 2023 | B15: 524769.7 | C15: 249232.73 | D15: =(B15-B11)/B11 * 100 -> 28.000151 | E15: =(C15-C11)/C11*100 -> 12.60527
A16: III кв. 2023 | B16: 573613.19 | C16: 264282.47 | D16: =(B16-B12)/B12 * 100 -> 23.178199 | E16: =(C16-C12)/C12*100 -> 17.871987
A17: IV кв. 2023 | B17: 638321.6 | C17: 285514.76 | D17: =(B17-B13)/B13 * 100 -> 30.586072 | E17: =(C17-C13)/C13*100 -> 15.909363
... A25: IV кв. 2025 | B25: 1214234 | C25: 781008.02 | D25: =(B25-B21)/B21 * 100 -> -7.4914952 | E25: =(C25-C21)/C21*100 -> -30.459779

Sheet Рентабельность
A1: Год | B1: ROE | C1: ROA
A2: 2019 | B2: 33 | C2: 8
A3: 2020 | B3: 29 | C3: 7
A4: 2021 | B4: 26 | C4: 6
A5: 2022 | B5: 20 | C5: 5
A6: 2023 | B6: 25 | C6: 7
A7: 2024 | B7: 31 | C7: 8
A8: 2025 | B8: 27 | C8: 8

Sheet Структура страховых премий
A1: Год | B1: Страховые брокеры | C1: Организации, торгующие ТС | D1: Юридические лица | E1: Физические лица и ИП | F1: Кредитные организации | G1: Без участия посредников | H1: Прочие посредники
A2: 2024 | B2: 3 | C2: 2 | D2: 4 | E2: 12.4 | F2: 54.3 | G2: 18.3 | H2: 6
A3: 2025 | B3: 3 | C3: 2 | D3: 4 | E3: 13 | F3: 52 | G3: 20 | H3: 6

Sheet Страхования (Кол-во премий)
A1: Год | B1: Страхование жизни | C1: Страхование от НС и болезней | D1: ДМС | E1: Автострахование (КАСКО) | F1: Имущество юрлиц | G1: Имущество граждан (ФЛ) | H1: ОСАГО | I1: Прочие виды
A2: 2017 | B2: =Лист5!F205 -> 4537172 | C2: =Лист5!F212 -> 59595204 | D2: =Лист5!F213 -> 11086927 | E2: =Лист5!F214 -> 3932793 | F2: =Лист5!F215 -> 423567 | G2: =Лист5!F216 -> 38296978 | H2: =Лист5!F217 -> 38164033 | I2: =Лист5!F218 -> 37075344
A3: 2018 | B3: =Лист5!J205 -> 6003845 | C3: =Лист5!J212 -> 57633509 | D3: =Лист5!J213 -> 12317853 | E3: =Лист5!J214 -> 4731289 | F3: =Лист5!J215 -> 729707 | G3: =Лист5!J216 -> 45662023 | H3: =Лист5!J217 -> 39704379 | I3: =Лист5!J218 -> 35773717
A4: 2019 | B4: =Лист5!N205 -> 5212447 | C4: =Лист5!N212 -> 55158256 | D4: =Лист5!N213 -> 17033842 | E4: =Лист5!N214 -> 4934083 | F4: =Лист5!N215 -> 440595 | G4: =Лист5!N216 -> 48790230 | H4: =Лист5!N217 -> 39691288 | I4: =Лист5!N218 -> 36849018
A5: 2020 | B5: =Лист5!R205 -> 5382538 | C5: =Лист5!R212 -> 39886810 | D5: =Лист5!R213 -> 10730002 | E5: =Лист5!R214 -> 5244630 | F5: =Лист5!R215 -> 409601 | G5: =Лист5!R216 -> 43219929 | H5: =Лист5!R217 -> 39659499 | I5: =Лист5!R218 -> 30571781
A6: 2021 | B6: =Лист5!V205 -> 6339933 | C6: =Лист5!V212 -> 64681020 | D6: =Лист5!V213 -> 12620220 | E6: =Лист5!V214 -> 5426989 | F6: =Лист5!V215 -> 548029 | G6: =Лист5!V216 -> 55334418 | H6: =Лист5!V217 -> 39923837 | I6: =Лист5!V218 -> 57365344
A7: 2022 | B7: =Лист5!Z205 -> 5167387 | C7: =Лист5!Z212 -> 59741237 | D7: =Лист5!Z213 -> 13014840 | E7: =Лист5!Z214 -> 6049534 | F7: =Лист5!Z215 -> 904109 | G7: =Лист5!Z216 -> 50976424 | H7: =Лист5!Z217 -> 40131233 | I7: =Лист5!Z218 -> 65326529
A8: 2023 | B8: =Лист5!AD205 -> 5220701 | C8: =Лист5!AD212 -> 87328998 | D8: =Лист5!AD213 -> 13860106 | E8: =Лист5!AD214 -> 8892968 | F8: =Лист5!AD215 -> 1048191 | G8: =Лист5!AD216 -> 61511189 | H8: =Лист5!AD217 -> 41315586 | I8: =Лист5!AD218 -> 81731244
A9: 2024 | B9: =Лист5!AH205 -> 4636721 | C9: =Лист5!AH212 -> 78698713 | D9: =Лист5!AH213 -> 15448136 | E9: =Лист5!AH214 -> 10578448 | F9: =Лист5!AH215 -> 1550643 | G9: =Лист5!AH216 -> 62552963 | H9: =Лист5!AH217 -> 44506337 | I9: =Лист5!AH218 -> 80597141
A10: 2025 | B10: =Лист5!AL205 -> 3968805 | C10: =Лист5!AL212 -> 103918576 | D10: =Лист5!AL213 -> 14688695 | E10: =Лист5!AL214 -> 10689599 | F10: =Лист5!AL215 -> 1801528 | G10: =Лист5!AL216 -> 94105982 | H10: =Лист5!AL217 -> 54435536 | I10: =Лист5!AL218 -> 111870261

Sheet Страхования (Сумма премий)
A1: Год | B1: Страхование жизни | C1: Страхование от НС и болезней | D1: ДМС | E1: Автострахование (КАСКО) | F1: Имущество юрлиц | G1: Имущество граждан (ФЛ) | H1: ОСАГО | I1: Прочие виды
A2: 2017 | B2: {=INDIRECT("Лист5!F"&188+(COLUMN()-COLUMN($A$1)))} -> 331536.83 | C2: {=INDIRECT("Лист5!F"&194+(COLUMN()-COLUMN($A$1)))} -> 121249.28 | D2: {=INDIRECT("Лист5!F"&194+(COLUMN()-COLUMN($A$1)))} -> 140007.95 | E2: {=INDIRECT("Лист5!F"&194+(COLUMN()-COLUMN($A$1)))} -> 162495.76 | F2: {=INDIRECT("Лист5!F"&194+(COLUMN()-COLUMN($A$1)))} -> 95988.475 | G2: {=INDIRECT("Лист5!F"&194+(COLUMN()-COLUMN($A$1)))} -> 57406.518 | H2: {=INDIRECT("Лист5!F"&194+(COLUMN()-COLUMN($A$1)))} -> 222075.98 | I2: {=INDIRECT("Лист5!F"&194+(COLUMN()-COLUMN($A$1)))} -> 148080.8
A3: 2018 | B3: {=INDIRECT("Лист5!J"&188+(COLUMN()-COLUMN($A$1)))} -> 452399.85 | C3: {=INDIRECT("Лист5!J"&194+(COLUMN()-COLUMN($A$1)))} -> 169520.92 | D3: {=INDIRECT("Лист5!J"&194+(COLUMN()-COLUMN($A$1)))} -> 151842.79 | E3: {=INDIRECT("Лист5!J"&194+(COLUMN()-COLUMN($A$1)))} -> 168691.76 | F3: {=INDIRECT("Лист5!J"&194+(COLUMN()-COLUMN($A$1)))} -> 88523.652 | G3: {=INDIRECT("Лист5!J"&194+(COLUMN()-COLUMN($A$1)))} -> 64810.514 | H3: {=INDIRECT("Лист5!J"&194+(COLUMN()-COLUMN($A$1)))} -> 225965.14 | I3: {=INDIRECT("Лист5!J"&194+(COLUMN()-COLUMN($A$1)))} -> 157746.5
A4: 2019 | B4: {=INDIRECT("Лист5!N"&188+(COLUMN()-COLUMN($A$1)))} -> 409374.11 | C4: {=INDIRECT("Лист5!N"&194+(COLUMN()-COLUMN($A$1)))} -> 187366.46 | D4: {=INDIRECT("Лист5!N"&194+(COLUMN()-COLUMN($A$1)))} -> 180654.79 | E4: {=INDIRECT("Лист5!N"&194+(COLUMN()-COLUMN($A$1)))} -> 170546.91 | F4: {=INDIRECT("Лист5!N"&194+(COLUMN()-COLUMN($A$1)))} -> 103322.3 | G4: {=INDIRECT("Лист5!N"&194+(COLUMN()-COLUMN($A$1)))} -> 71900.593 | H4: {=INDIRECT("Лист5!N"&194+(COLUMN()-COLUMN($A$1)))} -> 214948.98 | I4: {=INDIRECT("Лист5!N"&194+(COLUMN()-COLUMN($A$1)))} -> 143063.46
A5: 2020 | B5: {=INDIRECT("Лист5!R"&188+(COLUMN()-COLUMN($A$1)))} -> 430517.25 | C5: {=INDIRECT("Лист5!R"&194+(COLUMN()-COLUMN($A$1)))} -> 202309.86 | D5: {=INDIRECT("Лист5!R"&194+(COLUMN()-COLUMN($A$1)))} -> 176964.71 | E5: {=INDIRECT("Лист5!R"&194+(COLUMN()-COLUMN($A$1)))} -> 175422.87 | F5: {=INDIRECT("Лист5!R"&194+(COLUMN()-COLUMN($A$1)))} -> 113142.52 | G5: {=INDIRECT("Лист5!R"&194+(COLUMN()-COLUMN($A$1)))} -> 71650.464 | H5: {=INDIRECT("Лист5!R"&194+(COLUMN()-COLUMN($A$1)))} -> 220021.18 | I5: {=INDIRECT("Лист5!R"&194+(COLUMN()-COLUMN($A$1)))} -> 148671.88
A6: 2021 | B6: {=INDIRECT("Лист5!V"&188+(COLUMN()-COLUMN($A$1)))} -> 524402.37 | C6: {=INDIRECT("Лист5!V"&194+(COLUMN()-COLUMN($A$1)))} -> 261893.42 | D6: {=INDIRECT("Лист5!V"&194+(COLUMN()-COLUMN($A$1)))} -> 199927.19 | E6: {=INDIRECT("Лист5!V"&194+(COLUMN()-COLUMN($A$1)))} -> 207076.23 | F6: {=INDIRECT("Лист5!V"&194+(COLUMN()-COLUMN($A$1)))} -> 120193.47 | G6: {=INDIRECT("Лист5!V"&194+(COLUMN()-COLUMN($A$1)))} -> 81776.524 | H6: {=INDIRECT("Лист5!V"&194+(COLUMN()-COLUMN($A$1)))} -> 225548.35 | I6: {=INDIRECT("Лист5!V"&194+(COLUMN()-COLUMN($A$1)))} -> 187471.73
A7: 2022 | B7: {=INDIRECT("Лист5!Z"&188+(COLUMN()-COLUMN($A$1)))} -> 511299.22 | C7: {=INDIRECT("Лист5!Z"&194+(COLUMN()-COLUMN($A$1)))} -> 207182.37 | D7: {=INDIRECT("Лист5!Z"&194+(COLUMN()-COLUMN($A$1)))} -> 213702.21 | E7: {=INDIRECT("Лист5!Z"&194+(COLUMN()-COLUMN($A$1)))} -> 222845.42 | F7: {=INDIRECT("Лист5!Z"&194+(COLUMN()-COLUMN($A$1)))} -> 128641.8 | G7: {=INDIRECT("Лист5!Z"&194+(COLUMN()-COLUMN($A$1)))} -> 84251.618 | H7: {=INDIRECT("Лист5!Z"&194+(COLUMN()-COLUMN($A$1)))} -> 273103.36 | I7: {=INDIRECT("Лист5!Z"&194+(COLUMN()-COLUMN($A$1)))} -> 175721.64
A8: 2023 | B8: {=INDIRECT("Лист5!AD"&188+(COLUMN()-COLUMN($A$1)))} -> 775060.93 | C8: {=INDIRECT("Лист5!AD"&194+(COLUMN()-COLUMN($A$1)))} -> 200056.12 | D8: {=INDIRECT("Лист5!AD"&194+(COLUMN()-COLUMN($A$1)))} -> 253498.47 | E8: {=INDIRECT("Лист5!AD"&194+(COLUMN()-COLUMN($A$1)))} -> 270638.65 | F8: {=INDIRECT("Лист5!AD"&194+(COLUMN()-COLUMN($A$1)))} -> 133944.21 | G8: {=INDIRECT("Лист5!AD"&194+(COLUMN()-COLUMN($A$1)))} -> 117359.77 | H8: {=INDIRECT("Лист5!AD"&194+(COLUMN()-COLUMN($A$1)))} -> 324416.06 | I8: {=INDIRECT("Лист5!AD"&194+(COLUMN()-COLUMN($A$1)))} -> 210084.14
A9: 2024 | B9: {=INDIRECT("Лист5!AH"&188+(COLUMN()-COLUMN($A$1)))} -> 2033132.8 | C9: {=INDIRECT("Лист5!AH"&194+(COLUMN()-COLUMN($A$1)))} -> 168044.5 | D9: {=INDIRECT("Лист5!AH"&194+(COLUMN()-COLUMN($A$1)))} -> 328295.88 | E9: {=INDIRECT("Лист5!AH"&194+(COLUMN()-COLUMN($A$1)))} -> 323157.78 | F9: {=INDIRECT("Лист5!AH"&194+(COLUMN()-COLUMN($A$1)))} -> 150858.4 | G9: {=INDIRECT("Лист5!AH"&194+(COLUMN()-COLUMN($A$1)))} -> 126247.93 | H9: {=INDIRECT("Лист5!AH"&194+(COLUMN()-COLUMN($A$1)))} -> 331940.74 | I9: {=INDIRECT("Лист5!AH"&194+(COLUMN()-COLUMN($A$1)))} -> 258358.63
A10: 2025 | B10: {=INDIRECT("Лист5!AL"&188+(COLUMN()-COLUMN($A$1)))} -> 2253618.3 | C10: {=INDIRECT("Лист5!AL"&194+(COLUMN()-COLUMN($A$1)))} -> 157469.06 | D10: {=INDIRECT("Лист5!AL"&194+(COLUMN()-COLUMN($A$1)))} -> 323650.71 | E10: {=INDIRECT("Лист5!AL"&194+(COLUMN()-COLUMN($A$1)))} -> 338831.25 | F10: {=INDIRECT("Лист5!AL"&194+(COLUMN()-COLUMN($A$1)))} -> 170294.38 | G10: {=INDIRECT("Лист5!AL"&194+(COLUMN()-COLUMN($A$1)))} -> 136924.8 | H10: {=INDIRECT("Лист5!AL"&194+(COLUMN()-COLUMN($A$1)))} -> 330281.69 | I10: {=INDIRECT("Лист5!AL"&194+(COLUMN()-COLUMN($A$1)))} -> 265543.68

Sheet Страхования (Кол-во выплат)
A1: Год | B1: Страхование жизни | C1: Страхование от НС и болезней | D1: ДМС | E1: Автострахование (КАСКО) | F1: Имущество юрлиц | G1: Имущество граждан (ФЛ) | H1: ОСАГО | I1: Прочие виды
A2: 2017 | B2: {=INDIRECT("Лист5!F"&221+(COLUMN()-COLUMN($A$1)))} -> 654304 | C2: {=INDIRECT("Лист5!F"&227+(COLUMN()-COLUMN($A$1)))} -> 385891 | D2: {=INDIRECT("Лист5!F"&227+(COLUMN()-COLUMN($A$1)))} -> 13739975 | E2: {=INDIRECT("Лист5!F"&227+(COLUMN()-COLUMN($A$1)))} -> 976432 | F2: {=INDIRECT("Лист5!F"&227+(COLUMN()-COLUMN($A$1)))} -> 19502 | G2: {=INDIRECT("Лист5!F"&227+(COLUMN()-COLUMN($A$1)))} -> 209692 | H2: {=INDIRECT("Лист5!F"&227+(COLUMN()-COLUMN($A$1)))} -> 2949025 | I2: {=INDIRECT("Лист5!F"&227+(COLUMN()-COLUMN($A$1)))} -> 243844
A3: 2018 | B3: {=INDIRECT("Лист5!J"&221+(COLUMN()-COLUMN($A$1)))} -> 765007 | C3: {=INDIRECT("Лист5!J"&227+(COLUMN()-COLUMN($A$1)))} -> 452048 | D3: {=INDIRECT("Лист5!J"&227+(COLUMN()-COLUMN($A$1)))} -> 33934278 | E3: {=INDIRECT("Лист5!J"&227+(COLUMN()-COLUMN($A$1)))} -> 907291 | F3: {=INDIRECT("Лист5!J"&227+(COLUMN()-COLUMN($A$1)))} -> 18078 | G3: {=INDIRECT("Лист5!J"&227+(COLUMN()-COLUMN($A$1)))} -> 210930 | H3: {=INDIRECT("Лист5!J"&227+(COLUMN()-COLUMN($A$1)))} -> 2369375 | I3: {=INDIRECT("Лист5!J"&227+(COLUMN()-COLUMN($A$1)))} -> 237815
A4: 2019 | B4: {=INDIRECT("Лист5!N"&221+(COLUMN()-COLUMN($A$1)))} -> 847936 | C4: {=INDIRECT("Лист5!N"&227+(COLUMN()-COLUMN($A$1)))} -> 335214 | D4: {=INDIRECT("Лист5!N"&227+(COLUMN()-COLUMN($A$1)))} -> 39245088 | E4: {=INDIRECT("Лист5!N"&227+(COLUMN()-COLUMN($A$1)))} -> 945442 | F4: {=INDIRECT("Лист5!N"&227+(COLUMN()-COLUMN($A$1)))} -> 13684 | G4: {=INDIRECT("Лист5!N"&227+(COLUMN()-COLUMN($A$1)))} -> 173300 | H4: {=INDIRECT("Лист5!N"&227+(COLUMN()-COLUMN($A$1)))} -> 2293388 | I4: {=INDIRECT("Лист5!N"&227+(COLUMN()-COLUMN($A$1)))} -> 290080
A5: 2020 | B5: {=INDIRECT("Лист5!R"&221+(COLUMN()-COLUMN($A$1)))} -> 1112356 | C5: {=INDIRECT("Лист5!R"&227+(COLUMN()-COLUMN($A$1)))} -> 301180 | D5: {=INDIRECT("Лист5!R"&227+(COLUMN()-COLUMN($A$1)))} -> 43091647 | E5: {=INDIRECT("Лист5!R"&227+(COLUMN()-COLUMN($A$1)))} -> 897968 | F5: {=INDIRECT("Лист5!R"&227+(COLUMN()-COLUMN($A$1)))} -> 13895 | G5: {=INDIRECT("Лист5!R"&227+(COLUMN()-COLUMN($A$1)))} -> 187638 | H5: {=INDIRECT("Лист5!R"&227+(COLUMN()-COLUMN($A$1)))} -> 2070686 | I5: {=INDIRECT("Лист5!R"&227+(COLUMN()-COLUMN($A$1)))} -> 304726
A6: 2021 | B6: {=INDIRECT("Лист5!V"&221+(COLUMN()-COLUMN($A$1)))} -> 1865884 | C6: {=INDIRECT("Лист5!V"&227+(COLUMN()-COLUMN($A$1)))} -> 344284 | D6: {=INDIRECT("Лист5!V"&227+(COLUMN()-COLUMN($A$1)))} -> 47084420 | E6: {=INDIRECT("Лист5!V"&227+(COLUMN()-COLUMN($A$1)))} -> 948016 | F6: {=INDIRECT("Лист5!V"&227+(COLUMN()-COLUMN($A$1)))} -> 15276 | G6: {=INDIRECT("Лист5!V"&227+(COLUMN()-COLUMN($A$1)))} -> 188432 | H6: {=INDIRECT("Лист5!V"&227+(COLUMN()-COLUMN($A$1)))} -> 2151231 | I6: {=INDIRECT("Лист5!V"&227+(COLUMN()-COLUMN($A$1)))} -> 468303
A7: 2022 | B7: {=INDIRECT("Лист5!Z"&221+(COLUMN()-COLUMN($A$1)))} -> 1754912 | C7: {=INDIRECT("Лист5!Z"&227+(COLUMN()-COLUMN($A$1)))} -> 380461 | D7: {=INDIRECT("Лист5!Z"&227+(COLUMN()-COLUMN($A$1)))} -> 48063573 | E7: {=INDIRECT("Лист5!Z"&227+(COLUMN()-COLUMN($A$1)))} -> 947827 | F7: {=INDIRECT("Лист5!Z"&227+(COLUMN()-COLUMN($A$1)))} -> 16432 | G7: {=INDIRECT("Лист5!Z"&227+(COLUMN()-COLUMN($A$1)))} -> 236925 | H7: {=INDIRECT("Лист5!Z"&227+(COLUMN()-COLUMN($A$1)))} -> 2283943 | I7: {=INDIRECT("Лист5!Z"&227+(COLUMN()-COLUMN($A$1)))} -> 342954
A8: 2023 | B8: {=INDIRECT("Лист5!AD"&221+(COLUMN()-COLUMN($A$1)))} -> 1827921 | C8: {=INDIRECT("Лист5!AD"&227+(COLUMN()-COLUMN($A$1)))} -> 372927 | D8: {=INDIRECT("Лист5!AD"&227+(COLUMN()-COLUMN($A$1)))} -> 46332690 | E8: {=INDIRECT("Лист5!AD"&227+(COLUMN()-COLUMN($A$1)))} -> 810872 | F8: {=INDIRECT("Лист5!AD"&227+(COLUMN()-COLUMN($A$1)))} -> 16275 | G8: {=INDIRECT("Лист5!AD"&227+(COLUMN()-COLUMN($A$1)))} -> 201779 | H8: {=INDIRECT("Лист5!AD"&227+(COLUMN()-COLUMN($A$1)))} -> 2047108 | I8: {=INDIRECT("Лист5!AD"&227+(COLUMN()-COLUMN($A$1)))} -> 384360
A9: 2024 | B9: {=INDIRECT("Лист5!AH"&221+(COLUMN()-COLUMN($A$1)))} -> 3298677 | C9: {=INDIRECT("Лист5!AH"&227+(COLUMN()-COLUMN($A$1)))} -> 392890 | D9: {=INDIRECT("Лист5!AH"&227+(COLUMN()-COLUMN($A$1)))} -> 48246700 | E9: {=INDIRECT("Лист5!AH"&227+(COLUMN()-COLUMN($A$1)))} -> 872847 | F9: {=INDIRECT("Лист5!AH"&227+(COLUMN()-COLUMN($A$1)))} -> 22585 | G9: {=INDIRECT("Лист5!AH"&227+(COLUMN()-COLUMN($A$1)))} -> 274675 | H9: {=INDIRECT("Лист5!AH"&227+(COLUMN()-COLUMN($A$1)))} -> 2216610 | I9: {=INDIRECT("Лист5!AH"&227+(COLUMN()-COLUMN($A$1)))} -> 472941
A10: 2025 | B10: {=INDIRECT("Лист5!AL"&221+(COLUMN()-COLUMN($A$1)))} -> 2506373 | C10: {=INDIRECT("Лист5!AL"&227+(COLUMN()-COLUMN($A$1)))} -> 411499 | D10: {=INDIRECT("Лист5!AL"&227+(COLUMN()-COLUMN($A$1)))} -> 59669726 | E10: {=INDIRECT("Лист5!AL"&227+(COLUMN()-COLUMN($A$1)))} -> 1041468 | F10: {=INDIRECT("Лист5!AL"&227+(COLUMN()-COLUMN($A$1)))} -> 23145 | G10: {=INDIRECT("Лист5!AL"&227+(COLUMN()-COLUMN($A$1)))} -> 228783 | H10: {=INDIRECT("Лист5!AL"&227+(COLUMN()-COLUMN($A$1)))} -> 2086076 | I10: {=INDIRECT("Лист5!AL"&227+(COLUMN()-COLUMN($A$1)))} -> 684711

Sheet Страхования (Сумма выплат)
A1: Год | B1: Страхование жизни | C1: Страхование от НС и болезней | D1: ДМС | E1: Автострахование (КАСКО) | F1: Имущество юрлиц | G1: Имущество граждан (ФЛ) | H1: ОСАГО | I1: Прочие виды
A2: 2017 | B2: {=INDIRECT("Лист5!F"&238+(COLUMN()-COLUMN($A$1)))} -> 36486.836 | C2: {=INDIRECT("Лист5!F"&244+(COLUMN()-COLUMN($A$1)))} -> 14367.296 | D2: {=INDIRECT("Лист5!F"&244+(COLUMN()-COLUMN($A$1)))} -> 105811.24 | E2: {=INDIRECT("Лист5!F"&244+(COLUMN()-COLUMN($A$1)))} -> 83343.915 | F2: {=INDIRECT("Лист5!F"&244+(COLUMN()-COLUMN($A$1)))} -> 36598.289 | G2: {=INDIRECT("Лист5!F"&244+(COLUMN()-COLUMN($A$1)))} -> 8233.497 | H2: {=INDIRECT("Лист5!F"&244+(COLUMN()-COLUMN($A$1)))} -> 175516.25 | I2: {=INDIRECT("Лист5!F"&244+(COLUMN()-COLUMN($A$1)))} -> 49364.804
A3: 2018 | B3: {=INDIRECT("Лист5!J"&238+(COLUMN()-COLUMN($A$1)))} -> 67070.482 | C3: {=INDIRECT("Лист5!J"&244+(COLUMN()-COLUMN($A$1)))} -> 16403.953 | D3: {=INDIRECT("Лист5!J"&244+(COLUMN()-COLUMN($A$1)))} -> 111930.61 | E3: {=INDIRECT("Лист5!J"&244+(COLUMN()-COLUMN($A$1)))} -> 83254.171 | F3: {=INDIRECT("Лист5!J"&244+(COLUMN()-COLUMN($A$1)))} -> 49322.248 | G3: {=INDIRECT("Лист5!J"&244+(COLUMN()-COLUMN($A$1)))} -> 8964.4475 | H3: {=INDIRECT("Лист5!J"&244+(COLUMN()-COLUMN($A$1)))} -> 137901.72 | I3: {=INDIRECT("Лист5!J"&244+(COLUMN()-COLUMN($A$1)))} -> 47620.372
A4: 2019 | B4: {=INDIRECT("Лист5!N"&238+(COLUMN()-COLUMN($A$1)))} -> 133402.66 | C4: {=INDIRECT("Лист5!N"&244+(COLUMN()-COLUMN($A$1)))} -> 17289.315 | D4: {=INDIRECT("Лист5!N"&244+(COLUMN()-COLUMN($A$1)))} -> 126495.46 | E4: {=INDIRECT("Лист5!N"&244+(COLUMN()-COLUMN($A$1)))} -> 97207.977 | F4: {=INDIRECT("Лист5!N"&244+(COLUMN()-COLUMN($A$1)))} -> 28891.027 | G4: {=INDIRECT("Лист5!N"&244+(COLUMN()-COLUMN($A$1)))} -> 8840.209 | H4: {=INDIRECT("Лист5!N"&244+(COLUMN()-COLUMN($A$1)))} -> 142379.15 | I4: {=INDIRECT("Лист5!N"&244+(COLUMN()-COLUMN($A$1)))} -> 56359.628
A5: 2020 | B5: {=INDIRECT("Лист5!R"&238+(COLUMN()-COLUMN($A$1)))} -> 204495.69 | C5: {=INDIRECT("Лист5!R"&244+(COLUMN()-COLUMN($A$1)))} -> 19228.29 | D5: {=INDIRECT("Лист5!R"&244+(COLUMN()-COLUMN($A$1)))} -> 118206.69 | E5: {=INDIRECT("Лист5!R"&244+(COLUMN()-COLUMN($A$1)))} -> 97983.36 | F5: {=INDIRECT("Лист5!R"&244+(COLUMN()-COLUMN($A$1)))} -> 22292.812 | G5: {=INDIRECT("Лист5!R"&244+(COLUMN()-COLUMN($A$1)))} -> 8651.636 | H5: {=INDIRECT("Лист5!R"&244+(COLUMN()-COLUMN($A$1)))} -> 137371.4 | I5: {=INDIRECT("Лист5!R"&244+(COLUMN()-COLUMN($A$1)))} -> 50255.648
A6: 2021 | B6: {=INDIRECT("Лист5!V"&238+(COLUMN()-COLUMN($A$1)))} -> 288328.6 | C6: {=INDIRECT("Лист5!V"&244+(COLUMN()-COLUMN($A$1)))} -> 26928.836 | D6: {=INDIRECT("Лист5!V"&244+(COLUMN()-COLUMN($A$1)))} -> 142205.35 | E6: {=INDIRECT("Лист5!V"&244+(COLUMN()-COLUMN($A$1)))} -> 109260.95 | F6: {=INDIRECT("Лист5!V"&244+(COLUMN()-COLUMN($A$1)))} -> 22002.962 | G6: {=INDIRECT("Лист5!V"&244+(COLUMN()-COLUMN($A$1)))} -> 9084.8181 | H6: {=INDIRECT("Лист5!V"&244+(COLUMN()-COLUMN($A$1)))} -> 143555.73 | I6: {=INDIRECT("Лист5!V"&244+(COLUMN()-COLUMN($A$1)))} -> 55606.61
A7: 2022 | B7: {=INDIRECT("Лист5!Z"&238+(COLUMN()-COLUMN($A$1)))} -> 352200.51 | C7: {=INDIRECT("Лист5!Z"&244+(COLUMN()-COLUMN($A$1)))} -> 33092.666 | D7: {=INDIRECT("Лист5!Z"&244+(COLUMN()-COLUMN($A$1)))} -> 156051.34 | E7: {=INDIRECT("Лист5!Z"&244+(COLUMN()-COLUMN($A$1)))} -> 121548.73 | F7: {=INDIRECT("Лист5!Z"&244+(COLUMN()-COLUMN($A$1)))} -> 30679.097 | G7: {=INDIRECT("Лист5!Z"&244+(COLUMN()-COLUMN($A$1)))} -> 10363.958 | H7: {=INDIRECT("Лист5!Z"&244+(COLUMN()-COLUMN($A$1)))} -> 159834.13 | I7: {=INDIRECT("Лист5!Z"&244+(COLUMN()-COLUMN($A$1)))} -> 29448.343
A8: 2023 | B8: {=INDIRECT("Лист5!AD"&238+(COLUMN()-COLUMN($A$1)))} -> 469130.99 | C8: {=INDIRECT("Лист5!AD"&244+(COLUMN()-COLUMN($A$1)))} -> 31866.631 | D8: {=INDIRECT("Лист5!AD"&244+(COLUMN()-COLUMN($A$1)))} -> 169137.16 | E8: {=INDIRECT("Лист5!AD"&244+(COLUMN()-COLUMN($A$1)))} -> 129503.44 | F8: {=INDIRECT("Лист5!AD"&244+(COLUMN()-COLUMN($A$1)))} -> 30082.413 | G8: {=INDIRECT("Лист5!AD"&244+(COLUMN()-COLUMN($A$1)))} -> 10862.115 | H8: {=INDIRECT("Лист5!AD"&244+(COLUMN()-COLUMN($A$1)))} -> 161592.2 | I8: {=INDIRECT("Лист5!AD"&244+(COLUMN()-COLUMN($A$1)))} -> 42207.905
A9: 2024 | B9: {=INDIRECT("Лист5!AH"&238+(COLUMN()-COLUMN($A$1)))} -> 1412059 | C9: {=INDIRECT("Лист5!AH"&244+(COLUMN()-COLUMN($A$1)))} -> 36260.645 | D9: {=INDIRECT("Лист5!AH"&244+(COLUMN()-COLUMN($A$1)))} -> 191886.12 | E9: {=INDIRECT("Лист5!AH"&244+(COLUMN()-COLUMN($A$1)))} -> 165368.67 | F9: {=INDIRECT("Лист5!AH"&244+(COLUMN()-COLUMN($A$1)))} -> 65009.674 | G9: {=INDIRECT("Лист5!AH"&244+(COLUMN()-COLUMN($A$1)))} -> 17922.91 | H9: {=INDIRECT("Лист5!AH"&244+(COLUMN()-COLUMN($A$1)))} -> 202101.4 | I9: {=INDIRECT("Лист5!AH"&244+(COLUMN()-COLUMN($A$1)))} -> 58201.416
A10: 2025 | B10: {=INDIRECT("Лист5!AL"&238+(COLUMN()-COLUMN($A$1)))} -> 1662755.3 | C10: {=INDIRECT("Лист5!AL"&244+(COLUMN()-COLUMN($A$1)))} -> 37031.358 | D10: {=INDIRECT("Лист5!AL"&244+(COLUMN()-COLUMN($A$1)))} -> 233417.82 | E10: {=INDIRECT("Лист5!AL"&244+(COLUMN()-COLUMN($A$1)))} -> 217486.61 | F10: {=INDIRECT("Лист5!AL"&244+(COLUMN()-COLUMN($A$1)))} -> 65461.493 | G10: {=INDIRECT("Лист5!AL"&244+(COLUMN()-COLUMN($A$1)))} -> 15606.983 | H10: {=INDIRECT("Лист5!AL"&244+(COLUMN()-COLUMN($A$1)))} -> 221031.83 | I10: {=INDIRECT("Лист5!AL"&244+(COLUMN()-COLUMN($A$1)))} -> 95928.041

Sheet Лист5
A1: Ключевые показатели деятельности страховщиков | B1: Единица измерения | C1: 42825 | D1: 42916 | E1: 43008 | F1: 43100 | G1: 43190 | H1: 43281 | I1: 43373 | J1: 43465 | K1: 43555 | L1: 43646 | M1: 43738 | N1: 43830 | O1: 43921 | P1: 44012 | Q1: 44104 | R1: 44196 | S1: 44286 | T1: 44377 | U1: 44469 | V1: 44561 | W1: 44651 | X1: 44742 | Y1: 44834 | Z1: 44926 | AA1: 45016 | AB1: 45107 | AC1: 45199 | AD1: 45291 | AE1: 45382 | AF1: 45473 | AG1: 45565 | AH1: 45657 | AI1: 45747 | AJ1: 45838 | AK1: 45930 | AL1: 46022
A2: Количество субъектов страхового дела, в том числе: | B2: ед. | C2: 344 | D2: 326 | E2: 319 | F2: 309 | G2: 304 | H2: 293 | I2: 285 | J2: 275 | K2: 271 | L2: 268 | M2: 264 | N2: 255 | O2: 246 | P2: 242 | Q2: 237 | R2: 232 | S2: 231 | T2: 230 | U2: 225 | V2: 222 | W2: 222 | X2: 220 | Y2: 219 | Z2: 215 | AA2: 211 | AB2: 209 | AC2: 211 | AD2: 211 | AE2: 212 | AF2: 207 | AG2: 209 | AH2: 208 | AI2: 208 | AJ2: 208 | AK2: 204 | AL2: 204
A3: количество страховых организаций | B3: ед. | C3: 247 | D3: 242 | E3: 236 | F3: 226 | G3: 223 | H3: 214 | I3: 208 | J3: 199 | K3: 193 | L3: 188 | M3: 185 | N3: 178 | O3: 173 | P3: 169 | Q3: 165 | R3: 160 | S3: 160 | T3: 158 | U3: 151 | V3: 147 | W3: 146 | X3: 144 | Y3: 143 | Z3: 140 | AA3: 136 | AB3: 135 | AC3: 133 | AD3: 132 | AE3: 133 | AF3: 132 | AG3: 134 | AH3: 131 | AI3: 131 | AJ3: 131 | AK3: 128 | AL3: 129
A4: количество обществ взаимного страхования | B4: ед. | C4: 12 | D4: 12 | E4: 12 | F4: 12 | G4: 12 | H4: 12 | I4: 13 | J4: 12 | K4: 12 | L4: 12 | M4: 12 | N4: 11 | O4: 10 | P4: 10 | Q4: 11 | R4: 13 | S4: 14 | T4: 15 | U4: 16 | V4: 16 | W4: 18 | X4: 17 | Y4: 19 | Z4: 18 | AA4: 18 | AB4: 18 | AC4: 21 | AD4: 21 | AE4: 21 | AF4: 20 | AG4: 19 | AH4: 20 | AI4: 20 | AJ4: 19 | AK4: 18 | AL4: 15
A5: количество страховых брокеров | B5: ед. | C5: 85 | D5: 72 | E5: 71 | F5: 71 | G5: 69 | H5: 67 | I5: 64 | J5: 64 | K5: 66 | L5: 68 | M5: 67 | N5: 66 | O5: 63 | P5: 63 | Q5: 61 | R5: 59 | S5: 57 | T5: 57 | U5: 58 | V5: 59 | W5: 58 | X5: 59 | Y5: 57 | Z5: 57 | AA5: 57 | AB5: 56 | AC5: 57 | AD5: 58 | AE5: 58 | AF5: 55 | AG5: 56 | AH5: 57 | AI5: 57 | AJ5: 58 | AK5: 58 | AL5: 60
A6: Страховые премии (взносы) по договорам страхования1, в том числе по видам страхования: | B6: млн руб. | C6: 316317.26 | D6: 645970.79 | E6: 962439.9 | F6: 1278841.6 | G6: 377414.27 | H6: 731781.94 | I6: 1093836.2 | J6: 1479501.1 | K6: 378595.42 | L6: 739250.28 | M6: 1101338.4 | N6: 1481177.6 | O6: 426272.35 | P6: 739065.15 | Q6: 1135894.1 | R6: 1538700.7 | S6: 459799.28 | T6: 894187.3 | U6: 1356131.2 | V6: 1808289.3 | W6: 452281.34 | X6: 862257.19 | Y6: 1327934.7 | Z6: 1816747.6 | AA6: 548353.86 | AB6: 1073123.6 | AC6: 1646736.8 | AD6: 2285058.4 | AE6: 578425.59 | AF6: 1293612.6 | AG6: 2407471.9 | AH6: 3720036.7 | AI6: 845426.82 | AJ6: 1766648.4 | AK6: 2762379.9 | AL6: 3976613.9
A7: добровольное страхование жизни, в том числе: | B7: млн руб. | C7: 59830.624 | D7: 141230.79 | E7: 230882.38 | F7: 331536.83 | G7: 92220.753 | H7: 205718.56 | I7: 324903.61 | J7: 452399.85 | K7: 85238.37 | L7: 183698.92 | M7: 288007.67 | N7: 409374.11 | O7: 98832.577 | P7: 179177.16 | Q7: 299652.63 | R7: 430517.25 | S7: 106351.27 | T7: 235260.36 | U7: 379459.97 | V7: 524402.37 | W7: 94734.934 | X7: 218306.91 | Y7: 359260.72 | Z7: 511299.22 | AA7: 148359.67 | AB7: 342736.4 | AC7: 542954.94 | AD7: 775060.93 | AE7: 200824.31 | AF7: 487394.92 | AG7: 1160460.8 | AH7: 2033132.8 | AI7: 448847.92 | AJ7: 950556.36 | AK7: 1501216.6 | AL7: 2253618.3
A8: инвестиционное страхование жизни | B8: млн руб. | C8: nd | D8: nd | E8: nd | F8: nd | G8: nd | H8: nd | I8: nd | J8: nd | K8: nd | L8: 86515.724 | M8: 140999.34 | N8: 181984.85 | O8: 47500.67 | P8: 81428.463 | Q8: 128085.01 | R8: 182899.09 | S8: 44846.714 | T8: 100886.66 | U8: 158395.17 | V8: 219440.76 | W8: 30426.44 | X8: 51699.765 | Y8: 86469.1 | Z8: 118344.02 | AA8: 32625.186 | AB8: 80338.359 | AC8: 137978.99 | AD8: 207898.46 | AE8: 53441.94 | AF8: 145906.88 | AG8: 313985.54 | AH8: 501785.6 | AI8: 206574.97 | AJ8: 404380.18 | AK8: 607701.67 | AL8: 911462.84
A9: кредитное страхование жизни | B9: млн руб. | C9: nd | D9: nd | E9: nd | F9: nd | G9: nd | H9: nd | I9: nd | J9: nd | K9: nd | L9: nd | M9: nd | N9: nd | O9: nd | P9: nd | Q9: nd | R9: nd | S9: nd | T9: nd | U9: nd | V9: 136083.02 | W9: 22815.095 | X9: 44921.161 | Y9: 86314.725 | Z9: 135773.56 | AA9: 46076.736 | AB9: 107138.46 | AC9: 162077.32 | AD9: 204937.12 | AE9: 21288.227 | AF9: 44555.615 | AG9: 63824.627 | AH9: 76257.433 | AI9: 10500.885 | AJ9: 23809.596 | AK9: 47702.747 | AL9: 78180.88
A10: накопительное страхование жизни | B10: млн руб. | C10: nd | D10: nd | E10: nd | F10: nd | G10: nd | H10: nd | I10: nd | J10: nd | K10: nd | L10: nd | M10: nd | N10: nd | O10: nd | P10: nd | Q10: nd | R10: nd | S10: nd | T10: nd | U10: nd | V10: 156292.11 | W10: 39173.395 | X10: 117193.38 | Y10: 179405.79 | Z10: 247873.81 | AA10: 67387.401 | AB10: 149843.15 | AC10: 234831.67 | AD10: 352398.64 | AE10: 124032.17 | AF10: 292187.34 | AG10: 775659.05 | AH10: 1445877.8 | AI10: 229484.79 | AJ10: 518261.15 | AK10: 836885.04 | AL10: 1218029.9
A11: рисковое страхование жизни | B11: млн руб. | C11: nd | D11: nd | E11: nd | F11: nd | G11: nd | H11: nd | I11: nd | J11: nd | K11: nd | L11: nd | M11: nd | N11: nd | O11: nd | P11: nd | Q11: nd | R11: nd | S11: nd | T11: nd | U11: nd | V11: 8405.1326 | W11: 1339.4948 | X11: 2633.7412 | Y11: 4280.8273 | Z11: 5522.3159 | AA11: 1338.7969 | AB11: 2723.2937 | AC11: 4309.8344 | AD11: 4928.4984 | AE11: 951.42884 | AF11: 1741.386 | AG11: 2737.6528 | AH11: 3619.0061 | AI11: 584.92389 | AJ11: 1293.8409 | AK11: 2346.0793 | AL11: 1617.6072
A12: прочее страхование жизни | B12: млн руб. | C12: nd | D12: nd | E12: nd | F12: nd | G12: nd | H12: nd | I12: nd | J12: nd | K12: nd | L12: nd | M12: nd | N12: nd | O12: nd | P12: nd | Q12: nd | R12: nd | S12: nd | T12: nd | U12: nd | V12: 2011.0684 | W12: 524.91341 | X12: 1066.6455 | Y12: 1659.8941 | Z12: 2282.69 | AA12: 610.06064 | AB12: 1270.3602 | AC12: 1936.2908 | AD12: 2637.8168 | AE12: 717.63265 | AF12: 1477.9989 | AG12: 2244.7845 | AH12: 3047.8648 | AI12: 1172.0868 | AJ12: 1681.8901 | AK12: 2613.8636 | AL12: 6309.6423
A13: пенсионное страхование | B13: млн руб. | C13: 331.302 | D13: 694.377 | E13: 1023.262 | F13: 1438.842 | G13: 345.79347 | H13: 801.77634 | I13: 1168.2025 | J13: 1559.7758 | K13: 334.51559 | L13: 687.75495 | M13: 1703.9661 | N13: 2116.6406 | O13: 395.33401 | P13: 769.57547 | Q13: 1246.4981 | R13: 2267.814 | S13: 428.59651 | T13: 848.09288 | U13: 1670.9852 | V13: 2170.2675 | W13: 455.5947 | X13: 792.21618 | Y13: 1130.3878 | Z13: 1502.8261 | AA13: 321.48788 | AB13: 1422.7778 | AC13: 1820.8267 | AD13: 2260.3998 | AE13: 392.90691 | AF13: 1525.7043 | AG13: 2009.1274 | AH13: 2545.1595 | AI13: 530.2667 | AJ13: 1112.9277 | AK13: 3875.7257 | AL13: 7617.3108
A14: добровольное страхование от несчастных случаев и болезней | B14: млн руб. | C14: 24529.707 | D14: 55057.369 | E14: 87690.706 | F14: 121249.28 | G14: 31595.521 | H14: 70083.992 | I14: 114229.92 | J14: 169520.92 | K14: 42376.931 | L14: 90491.37 | M14: 137676.05 | N14: 187366.46 | O14: 48702.416 | P14: 87735.376 | Q14: 143338.57 | R14: 202309.86 | S14: 63193.496 | T14: 132955.69 | U14: 200789.95 | V14: 261893.42 | W14: 41229.222 | X14: 79959.068 | Y14: 141964.67 | Z14: 207182.37 | AA14: 56014.702 | AB14: 111688.87 | AC14: 161219.82 | AD14: 200056.12 | AE14: 38856.683 | AF14: 81917.184 | AG14: 128090.92 | AH14: 168044.5 | AI14: 42579.825 | AJ14: 77190.122 | AK14: 118681.7 | AL14: 157469.06
A15: добровольное медицинское страхование | B15: млн руб. | C15: 68544.815 | D15: 98075.609 | E15: 120896.67 | F15: 140007.95 | G15: 72521.276 | H15: 104079.55 | I15: 129844.71 | J15: 151842.79 | K15: 77878.189 | L15: 115606.29 | M15: 150418.07 | N15: 180654.79 | O15: 84573.315 | P15: 116804.28 | Q15: 147570.62 | R15: 176964.71 | S15: 86959.055 | T15: 127172.24 | U15: 163973.74 | V15: 199927.19 | W15: 93050.449 | X15: 140001.83 | Y15: 176784.09 | Z15: 213702.21 | AA15: 91740.959 | AB15: 125095.82 | AC15: 176131.56 | AD15: 253498.47 | AE15: 77563.324 | AF15: 172940.78 | AG15: 245222.01 | AH15: 328295.88 | AI15: 79946.596 | AJ15: 161328 | AK15: 241199.32 | AL15: 323650.71
A16: добровольное страхование средств наземного транспорта (кроме средств железнодорожного транспорта) | B16: млн руб. | C16: 36750.187 | D16: 77730.511 | E16: 118021.59 | F16: 162495.76 | G16: 36708.358 | H16: 80141.781 | I16: 121448.13 | J16: 168691.76 | K16: 35961.216 | L16: 78276.577 | M16: 121506.38 | N16: 170546.91 | O16: 39349.92 | P16: 75544.924 | Q16: 123062.87 | R16: 175422.87 | S16: 44581.446 | T16: 93188.307 | U16: 147998.32 | V16: 207076.23 | W16: 51587.739 | X16: 103326.38 | Y16: 160597.25 | Z16: 222845.42 | AA16: 58446.426 | AB16: 120489.96 | AC16: 192624.84 | AD16: 270638.65 | AE16: 71393.336 | AF16: 147297.09 | AG16: 236252.13 | AH16: 323157.78 | AI16: 69680.354 | AJ16: 149600.07 | AK16: 240695.2 | AL16: 338831.25
A17: добровольное страхование имущества юридических лиц (кроме транспортных средств, грузов и сельскохозяйственного страхования) | B17: млн руб. | C17: 25748.87 | D17: 52351.977 | E17: 79916.424 | F17: 95988.475 | G17: 34277.535 | H17: 53473.471 | I17: 76832.006 | J17: 88523.652 | K17: 33527.903 | L17: 56957.95 | M17: 84873.797 | N17: 103322.3 | O17: 43557.373 | P17: 67732.147 | Q17: 96562.788 | R17: 113142.52 | S17: 37533.813 | T17: 65632.02 | U17: 96748.073 | V17: 120193.47 | W17: 41774.617 | X17: 69467.887 | Y17: 104558.91 | Z17: 128641.8 | AA17: 40128.167 | AB17: 71601.167 | AC17: 102697.68 | AD17: 133944.21 | AE17: 35319.2 | AF17: 72216.525 | AG17: 113608.3 | AH17: 150858.4 | AI17: 40703.303 | AJ17: 83297.206 | AK17: 127373.78 | AL17: 170294.38
A18: добровольное страхование имущества граждан (кроме транспортных средств, грузов и сельскохозяйственного страхования) | B18: млн руб. | C18: 11470.293 | D18: 25397.171 | E18: 41148.174 | F18: 57406.518 | G18: 13402.614 | H18: 28315.86 | I18: 45517.844 | J18: 64810.514 | K18: 14488.979 | L18: 30900.539 | M18: 49562.805 | N18: 71900.593 | O18: 15856.319 | P18: 30266.589 | Q18: 50088.244 | R18: 71650.464 | S18: 17012.953 | T18: 35786.464 | U18: 57421.623 | V18: 81776.524 | W18: 18577.054 | X18: 37380.215 | Y18: 59161.176 | Z18: 84251.618 | AA18: 29133.573 | AB18: 50961.955 | AC18: 83190.867 | AD18: 117359.77 | AE18: 25943.313 | AF18: 56712.743 | AG18: 89918.504 | AH18: 126247.93 | AI18: 29148.195 | AJ18: 62101.43 | AK18: 98419.808 | AL18: 136924.8
A19: обязательное страхование гражданской ответственности владельцев транспортных средств | B19: млн руб. | C19: 48237.933 | D19: 109191.87 | E19: 165254.33 | F19: 222075.98 | G19: 46019.624 | H19: 107302.33 | I19: 165077.84 | J19: 225965.14 | K19: 45118.364 | L19: 101588.39 | M19: 153986.88 | N19: 214948.98 | O19: 46464.982 | P19: 102961.12 | Q19: 163784.74 | R19: 220021.18 | S19: 49977.035 | T19: 109462.1 | U19: 171987.23 | V19: 225548.35 | W19: 52401.515 | X19: 117999.41 | Y19: 191260.89 | Z19: 273103.36 | AA19: 68957.242 | AB19: 151928.94 | AC19: 235236.19 | AD19: 324416.06 | AE19: 72903.201 | AF19: 154908.18 | AG19: 242721.89 | AH19: 331940.74 | AI19: 73890.157 | AJ19: 156499.02 | AK19: 240222.68 | AL19: 330281.69
A20: прочие виды | B20: млн руб. | C20: 41204.832 | D20: 86935.488 | E20: 118629.63 | F20: 148080.8 | G20: 50668.586 | H20: 82666.395 | I20: 115982.09 | J20: 157746.5 | K20: 44005.464 | L20: 81730.238 | M20: 115306.78 | N20: 143063.46 | O20: 48935.449 | P20: 78843.556 | Q20: 111833.66 | R20: 148671.88 | S20: 54190.214 | T20: 94730.114 | U20: 137752.27 | V20: 187471.73 | W20: 58925.813 | X20: 95815.489 | Y20: 134347 | Z20: 175721.64 | AA20: 55573.127 | AB20: 98620.455 | AC20: 152680.86 | AD20: 210084.14 | AE20: 55622.226 | AF20: 120225.19 | AG20: 191197.38 | AH20: 258358.63 | AI20: 60630.466 | AJ20: 126076.22 | AK20: 194570.8 | AL20: 265543.68
A21: Страховые премии по договорам страхования, заключенным с физическими лицами | B21: млн руб. | C21: 156611.36 | D21: 357297.49 | E21: 561368.61 | F21: 780226.29 | G21: 189032.85 | H21: 427880.42 | I21: 678146.33 | J21: 958216.03 | K21: 204518.28 | L21: 357905.43 | M21: 691368.57 | N21: 964397.27 | O21: 227290.26 | P21: 431012.55 | Q21: 705943.81 | R21: 993538.33 | S21: 255134.96 | T21: 553309.95 | U21: 872004.55 | V21: 1178314.3 | W21: 225317.35 | X21: 489280.82 | Y21: 802781.86 | Z21: 1131686.9 | AA21: 315905.13 | AB21: 666490.19 | AC21: 1048039 | AD21: 1460314.1 | AE21: 373361.11 | AF21: 864137.83 | AG21: 1749295.5 | AH21: 2818401.6 | AI21: 623744.09 | AJ21: 1309175.9 | AK21: 2060679.9 | AL21: 3022415.8
A22: Страховые премии по договорам страхования, заключенным с индивидуальными предпринимателями и юридическими лицами | B22: млн руб. | C22: 159705.9 | D22: 288673.3 | E22: 401156.66 | F22: 497358.61 | G22: 187764.47 | H22: 303023.66 | I22: 414270.64 | J22: 520189.49 | K22: 173602.67 | L22: 278947.91 | M22: 409081.43 | N22: 515277.93 | O22: 199024.26 | P22: 309188.93 | Q22: 430095.62 | R22: 543928.41 | S22: 204519.36 | T22: 340549.94 | U22: 482628.97 | V22: 629975.02 | W22: 226963.99 | X22: 372976.37 | Y22: 525152.85 | Z22: 685060.71 | AA22: 232448.74 | AB22: 406633.38 | AC22: 598697.76 | AD22: 824744.22 | AE22: 205064.48 | AF22: 429474.79 | AG22: 658176.45 | AH22: 901635.06 | AI22: 221682.73 | AJ22: 457472.56 | AK22: 701699.91 | AL22: 954198.09
A23: Количество договоров страхования, заключенные в отчетном периоде, в том числе по видам страхования: | B23: ед. | C23: 37613429 | D23: 88543007 | E23: 134544082 | F23: 193112018 | G23: 40722085 | H23: 94456832 | I23: 150577443 | J23: 202556322 | K23: 43507166 | L23: 99264916 | M23: 150839701 | N23: 208109759 | O23: 40168096 | P23: 77911339 | Q23: 126326422 | R23: 175104790 | S23: 41214799 | T23: 96294529 | U23: 184812918 | V23: 242239790 | W23: 46762408 | X23: 105882485 | Y23: 168319245 | Z23: 241311293 | AA23: 52505366 | AB23: 121079717 | AC23: 216397793 | AD23: 300908983 | AE23: 54851057 | AF23: 127656532 | AG23: 212064368 | AH23: 298569102 | AI23: 54639725 | AJ23: 143709786 | AK23: 211707407 | AL23: 395478982
A24: добровольное страхование жизни, в том числе: | B24: ед. | C24: 987727 | D24: 2104614 | E24: 3259946 | F24: 4537172 | G24: 884299 | H24: 2619310 | I24: 4427162 | J24: 6003845 | K24: 1136304 | L24: 2399410 | M24: 3712652 | N24: 5212447 | O24: 1097530 | P24: 2112822 | Q24: 3669583 | R24: 5382538 | S24: 1377994 | T24: 2944281 | U24: 4612065 | V24: 6339933 | W24: 1118085 | X24: 2202664 | Y24: 3738200 | Z24: 5167387 | AA24: 1278614 | AB24: 2702432 | AC24: 4320953 | AD24: 5220701 | AE24: 1182527 | AF24: 2472645 | AG24: 3464418 | AH24: 4636721 | AI24: 1562792 | AJ24: 9060298 | AK24: 2837172 | AL24: 3968805
A25: инвестиционное страхование жизни | B25: ед. | C25: nd | D25: nd | E25: nd | F25: nd | G25: nd | H25: nd | I25: nd | J25: nd | K25: nd | L25: 177499 | M25: 255022 | N25: 330192 | O25: 87539 | P25: 151037 | Q25: 310029 | R25: 347190 | S25: 80160 | T25: 173985 | U25: 267498 | V25: 360598 | W25: 52813 | X25: 89977 | Y25: 134739 | Z25: 169390 | AA25: 33030 | AB25: 65992 | AC25: 95751 | AD25: 132905 | AE25: 25474 | AF25: 37146 | AG25: 48632 | AH25: 71837 | AI25: 12258 | AJ25: 26998 | AK25: 40633 | AL25: 59635
A26: кредитное страхование жизни | B26: ед. | C26: nd | D26: nd | E26: nd | F26: nd | G26: nd | H26: nd | I26: nd | J26: nd | K26: nd | L26: nd | M26: nd | N26: nd | O26: nd | P26: nd | Q26: nd | R26: nd | S26: nd | T26: nd | U26: nd | V26: 4935066 | W26: 916066 | X26: 1734423 | Y26: 2977895 | Z26: 4169898 | AA26: 897346 | AB26: 1928534 | AC26: 3066195 | AD26: 3880748 | AE26: 669990 | AF26: 1561196 | AG26: 2384217 | AH26: 2972571 | AI26: 1258342 | AJ26: 7586811 | AK26: 1506362 | AL26: 2103425
A27: накопительное страхование жизни | B27: ед. | C27: nd | D27: nd | E27: nd | F27: nd | G27: nd | H27: nd | I27: nd | J27: nd | K27: nd | L27: nd | M27: nd | N27: nd | O27: nd | P27: nd | Q27: nd | R27: nd | S27: nd | T27: nd | U27: nd | V27: 478326 | W27: 80723 | X27: 233397 | Y27: 381343 | Z27: 508947 | AA27: 204551 | AB27: 415052 | AC27: 715084 | AD27: 977131 | AE27: 442411 | AF27: 791727 | AG27: 909864 | AH27: 1423134 | AI27: 237577 | AJ27: 1342233 | AK27: 1132885 | AL27: 1466758
A28: рисковое страхование жизни | B28: ед. | C28: nd | D28: nd | E28: nd | F28: nd | G28: nd | H28: nd | I28: nd | J28: nd | K28: nd | L28: nd | M28: nd | N28: nd | O28: nd | P28: nd | Q28: nd | R28: nd | S28: nd | T28: nd | U28: nd | V28: 512312 | W28: 56460 | X28: 120852 | Y28: 207299 | Z28: 268802 | AA28: 131961 | AB28: 268946 | AC28: 407750 | AD28: 180427 | AE28: 33473 | AF28: 59324 | AG28: 85770 | AH28: 118908 | AI28: 42927 | AJ28: 80139 | AK28: 115933 | AL28: 208836
A29: прочее страхование жизни | B29: ед. | C29: nd | D29: nd | E29: nd | F29: nd | G29: nd | H29: nd | I29: nd | J29: nd | K29: nd | L29: nd | M29: nd | N29: nd | O29: nd | P29: nd | Q29: nd | R29: nd | S29: nd | T29: nd | U29: nd | V29: 45784 | W29: 9807 | X29: 19835 | Y29: 30602 | Z29: 42299 | AA29: 9656 | AB29: 19329 | AC29: 29113 | AD29: 39634 | AE29: 9121 | AF29: 18183 | AG29: 27616 | AH29: 37700 | AI29: 8845 | AJ29: 18031 | AK29: 27712 | AL29: 103257
A30: пенсионное страхование | B30: ед. | C30: 1000 | D30: 1939 | E30: 2774 | F30: 3745 | G30: 709 | H30: 3204 | I30: 4165 | J30: 6951 | K30: 814 | L30: 2094 | M30: 3493 | N30: 6388 | O30: 1701 | P30: 2906 | Q30: 4662 | R30: 6710 | S30: 1637 | T30: 3379 | U30: 5232 | V30: 7847 | W30: 2216 | X30: 4180 | Y30: 6322 | Z30: 8051 | AA30: 2070 | AB30: 4579 | AC30: 7060 | AD30: 9856 | AE30: 2058 | AF30: 5069 | AG30: 8319 | AH30: 12571 | AI30: 2843 | AJ30: 6072 | AK30: 9391 | AL30: 13842
A31: добровольное страхование от несчастных случаев и болезней | B31: ед. | C31: 11279912 | D31: 25617944 | E31: 40392954 | F31: 59595204 | G31: 11479391 | H31: 25788842 | I31: 43151617 | J31: 57633509 | K31: 11642737 | L31: 26871224 | M31: 40252592 | N31: 55158256 | O31: 9339975 | P31: 16793049 | Q31: 27876557 | R31: 39886810 | S31: 9990992 | T31: 23742278 | U31: 50188124 | V31: 64681020 | W31: 10675132 | X31: 25243029 | Y31: 41429022 | Z31: 59741237 | AA31: 12397021 | AB31: 32705061 | AC31: 63423400 | AD31: 87328998 | AE31: 13361895 | AF31: 32394923 | AG31: 55183753 | AH31: 78698713 | AI31: 15864505 | AJ31: 38964298 | AK31: 53213197 | AL31: 103918576
A32: добровольное медицинское страхование | B32: ед. | C32: 2218522 | D32: 6726658 | E32: 9193538 | F32: 11086927 | G32: 2333279 | H32: 7125341 | I32: 9942280 | J32: 12317853 | K32: 3202107 | L32: 9411611 | M32: 13975836 | N32: 17033842 | O32: 3174577 | P32: 6243716 | Q32: 8260416 | R32: 10730002 | S32: 2171473 | T32: 6824056 | U32: 9932286 | V32: 12620220 | W32: 2779693 | X32: 7120886 | Y32: 10112291 | Z32: 13014840 | AA32: 2831232 | AB32: 7368468 | AC32: 10228582 | AD32: 13860106 | AE32: 3442143 | AF32: 8950433 | AG32: 12280618 | AH32: 15448136 | AI32: 3012995 | AJ32: 8075242 | AK32: 11602465 | AL32: 14688695
A33: добровольное страхование средств наземного транспорта (кроме средств железнодорожного транспорта) | B33: ед. | C33: 772964 | D33: 1750832 | E33: 2774549 | F33: 3932793 | G33: 926844 | H33: 2175289 | I33: 3427706 | J33: 4731289 | K33: 951686 | L33: 2229859 | M33: 3413369 | N33: 4934083 | O33: 1069070 | P33: 2436373 | Q33: 4192313 | R33: 5244630 | S33: 1159208 | T33: 2542393 | U33: 4102329 | V33: 5426989 | W33: 1242845 | X33: 2522061 | Y33: 4047737 | Z33: 6049534 | AA33: 1782857 | AB33: 3798880 | AC33: 6147123 | AD33: 8892968 | AE33: 2306204 | AF33: 4879532 | AG33: 7503103 | AH33: 10578448 | AI33: 2101407 | AJ33: 4573688 | AK33: 7432243 | AL33: 10689599
A34: добровольное страхование имущества юридических лиц (кроме транспортных средств, грузов и сельскохозяйственного страхования) | B34: ед. | C34: 86844 | D34: 196816 | E34: 297745 | F34: 423567 | G34: 98425 | H34: 226950 | I34: 355832 | J34: 729707 | K34: 110306 | L34: 198787 | M34: 313282 | N34: 440595 | O34: 87108 | P34: 174563 | Q34: 281678 | R34: 409601 | S34: 111688 | T34: 241396 | U34: 365859 | V34: 548029 | W34: 155779 | X34: 386065 | Y34: 675838 | Z34: 904109 | AA34: 247263 | AB34: 498805 | AC34: 744618 | AD34: 1048191 | AE34: 225290 | AF34: 502793 | AG34: 1085090 | AH34: 1550643 | AI34: 368201 | AJ34: 775738 | AK34: 1273613 | AL34: 1801528
A35: добровольное страхование имущества граждан (кроме транспортных средств, грузов и сельскохозяйственного страхования) | B35: ед. | C35: 7144725 | D35: 16152109 | E35: 26414031 | F35: 38296978 | G35: 9097757 | H35: 19900065 | I35: 32929748 | J35: 45662023 | K35: 11068885 | L35: 22719927 | M35: 34639536 | N35: 48790230 | O35: 9472615 | P35: 18747677 | Q35: 30896378 | R35: 43219929 | S35: 9569026 | T35: 20539107 | U35: 41838292 | V35: 55334418 | W35: 10181116 | X35: 21676301 | Y35: 34287803 | Z35: 50976424 | AA35: 11151218 | AB35: 22878423 | AC35: 42610482 | AD35: 61511189 | AE35: 12026877 | AF35: 25985300 | AG35: 44007838 | AH35: 62552963 | AI35: 9610133 | AJ35: 26073161 | AK35: 40653785 | AL35: 94105982
A36: обязательное страхование гражданской ответственности владельцев транспортных средств | B36: ед. | C36: 8030286 | D36: 20009718 | E36: 28255512 | F36: 38164033 | G36: 7928744 | H36: 18988504 | I36: 29077231 | J36: 39704379 | K36: 8091138 | L36: 18936130 | M36: 28539062 | N36: 39691288 | O36: 8314528 | P36: 18924269 | Q36: 29946173 | R36: 39659499 | S36: 8690823 | T36: 19717846 | U36: 30842382 | V36: 39923837 | W36: 8567068 | X36: 18922994 | Y36: 29528199 | Z36: 40131233 | AA36: 8507289 | AB36: 19568736 | AC36: 30364533 | AD36: 41315586 | AE36: 8805996 | AF36: 20010344 | AG36: 31878482 | AH36: 44506337 | AI36: 10049994 | AJ36: 22349565 | AK36: 37192788 | AL36: 54435536
A37: прочие виды | B37: ед. | C37: 7092449 | D37: 15984316 | E37: 23955807 | F37: 37075344 | G37: 7973346 | H37: 17632531 | I37: 27265867 | J37: 35773717 | K37: 7304003 | L37: 16497968 | M37: 25993372 | N37: 36849018 | O37: 7612693 | P37: 12478870 | Q37: 21203324 | R37: 30571781 | S37: 8143595 | T37: 19743172 | U37: 42931581 | V37: 57365344 | W37: 12042690 | X37: 27808485 | Y37: 44500155 | Z37: 65326529 | AA37: 14309872 | AB37: 31558912 | AC37: 58558102 | AD37: 81731244 | AE37: 13500125 | AF37: 32460562 | AG37: 56661066 | AH37: 80597141 | AI37: 12069698 | AJ37: 33837796 | AK37: 57502144 | AL37: 111870261
A38: Количество заключенных договоров страхования с физическими лицами | B38: ед. | C38: 33494442 | D38: 79842837 | E38: 121321859 | F38: 175409741 | G38: 35847669 | H38: 84814372 | I38: 135287066 | J38: 181375050 | K38: 38863595 | L38: 88843920 | M38: 134880969 | N38: 185858478 | O38: 35361537 | P38: 69072819 | Q38: 112394749 | R38: 153748177 | S38: 35924142 | T38: 83543466 | U38: 163949577 | V38: 212238717 | W38: 39197558 | X38: 89215154 | Y38: 140267949 | Z38: 202491876 | AA38: 43449446 | AB38: 97659956 | AC38: 177540072 | AD38: 247710761 | AE38: 47215728 | AF38: 109900839 | AG38: 184694032 | AH38: 260842530 | AI38: 47651173 | AJ38: 114247957 | AK38: 185621821 | AL38: 359321637
A39: Количество заключенных договоров страхования с индивидуальными предпринимателями и юридическими лицами | B39: ед. | C39: 4118987 | D39: 8700170 | E39: 13222223 | F39: 17702277 | G39: 4874416 | H39: 9642460 | I39: 15290377 | J39: 21181272 | K39: 4643571 | L39: 10420996 | M39: 15958732 | N39: 22251281 | O39: 4806559 | P39: 8838520 | Q39: 13931673 | R39: 21356613 | S39: 5290657 | T39: 12751063 | U39: 20863341 | V39: 30001073 | W39: 7564850 | X39: 16667331 | Y39: 28051296 | Z39: 38819417 | AA39: 9055920 | AB39: 23419761 | AC39: 38857721 | AD39: 53198222 | AE39: 7635329 | AF39: 17755693 | AG39: 27370336 | AH39: 37726572 | AI39: 6988552 | AJ39: 29461829 | AK39: 26085586 | AL39: 36157345
A40: Средняя страховая премия, в том числе по видам страхования: | B40: тыс руб. | C40: 8.4096896 | D40: 7.2955596 | E40: 7.1533425 | F40: 6.6222787 | G40: 9.2680487 | H40: 7.7472633 | I40: 7.2642763 | J40: 7.3041469 | K40: 8.7019094 | L40: 7.4472463 | M40: 7.3013831 | N40: 7.1172904 | O40: 10.612212 | P40: 9.4859768 | Q40: 8.9917383 | R40: 8.7873138 | S40: 11.156169 | T40: 9.2859616 | U40: 7.3378593 | V40: 7.464873 | W40: 9.6719002 | X40: 8.1435299 | Y40: 7.8893814 | Z40: 7.5286474 | AA40: 10.443768 | AB40: 8.8629507 | AC40: 7.6097669 | AD40: 7.5938522 | AE40: 10.545386 | AF40: 10.13354 | AG40: 11.352553 | AH40: 12.45955 | AI40: 15.47275 | AJ40: 12.293167 | AK40: 13.048102 | AL40: 10.055184
...
